Workbook

Sheet Bruto Reportes Nuevo
A1: MES | B1: SEMANA | C1: SEMANA - FECHA DE VIERNES | D1: GESTOR | E1: FECHA_COMPRA | F1: FECHA_VENTA | G1: FECHA_RMA | H1: CANTIDAD_REGISTROS | I1: COSTO_USD+ | J1: AGENTE
A2: =IF($C2<>"",_xlfn.CONCAT(MID(YEAR($C2),3,2),"M",MONTH($C2)),"") -> 26M1 | B2: =IF($C2<>"",_xlfn.CONCAT(MID(YEAR($C2),3,2),"W",WEEKNUM($C2,2)),"") -> 26W1 | C2: 46024 | D2: Intcomex | E2: 44490 | F2: 2022-02-07 | G2: 45203 | H2: 25 | I2: 1487.03 | J2: =IFERROR(INDEX(ListaGestores!B:B,MATCH(D2,ListaGestores!A:A,0)),"Revisar Datos") -> EMAA
A3: =IF($C3<>"",_xlfn.CONCAT(MID(YEAR($C3),3,2),"M",MONTH($C3)),"") -> 26M1 | B3: =IF($C3<>"",_xlfn.CONCAT(MID(YEAR($C3),3,2),"W",WEEKNUM($C3,2)),"") -> 26W1 | C3: 46024 | D3: Allplus | E3: 44669 | F3: 2022-05-13 | G3: 45203 | H3: 12 | I3: 567.52 | J3: =IFERROR(INDEX(ListaGestores!B:B,MATCH(D3,ListaGestores!A:A,0)),"Revisar Datos") -> EMAA
A4: =IF($C4<>"",_xlfn.CONCAT(MID(YEAR($C4),3,2),"M",MONTH($C4)),"") -> 26M1 | B4: =IF($C4<>"",_xlfn.CONCAT(MID(YEAR($C4),3,2),"W",WEEKNUM($C4,2)),"") -> 26W1 | C4: 46024 | D4: ASUS | E4: 45166 | F4: 2024-02-19 | G4: 45378 | H4: 37 | I4: 4531.83 | J4: =IFERROR(INDEX(ListaGestores!B:B,MATCH(D4,ListaGestores!A:A,0)),"Revisar Datos") -> EMAA
A5: =IF($C5<>"",_xlfn.CONCAT(MID(YEAR($C5),3,2),"M",MONTH($C5)),"") -> 26M1 | B5: =IF($C5<>"",_xlfn.CONCAT(MID(YEAR($C5),3,2),"W",WEEKNUM($C5,2)),"") -> 26W1 | C5: 46024 | D5: Micro Informatica - AMD | E5: 44484 | F5: 2021-11-03 | G5: 45516 | H5: 28 | I5: 6771.53 | J5: =IFERROR(INDEX(ListaGestores!B:B,MATCH(D5,ListaGestores!A:A,0)),"Revisar Datos") -> MATIASNG
A6: =IF($C6<>"",_xlfn.CONCAT(MID(YEAR($C6),3,2),"M",MONTH($C6)),"") -> 26M1 | B6: =IF($C6<>"",_xlfn.CONCAT(MID(YEAR($C6),3,2),"W",WEEKNUM($C6,2)),"") -> 26W1 | C6: 46024 | D6: Ma Labs | E6: 45477 | F6: 2024-07-12 | G6: 45525 | H6: 3 | I6: 470.73 | J6: =IFERROR(INDEX(ListaGestores!B:B,MATCH(D6,ListaGestores!A:A,0)),"Revisar Datos") -> REINHART
A7: =IF($C7<>"",_xlfn.CONCAT(MID(YEAR($C7),3,2),"M",MONTH($C7)),"") -> 26M1 | B7: =IF($C7<>"",_xlfn.CONCAT(MID(YEAR($C7),3,2),"W",WEEKNUM($C7,2)),"") -> 26W1 | C7: 46024 | D7: AS Tienda Tecno | E7: 44916 | F7: 2024-03-17 | G7: 45582 | H7: 1 | I7: 60.16 | J7: =IFERROR(INDEX(ListaGestores!B:B,MATCH(D7,ListaGestores!A:A,0)),"Revisar Datos") -> JAVIERS
A8: =IF($C8<>"",_xlfn.CONCAT(MID(YEAR($C8),3,2),"M",MONTH($C8)),"") -> 26M1 | B8: =IF($C8<>"",_xlfn.CONCAT(MID(YEAR($C8),3,2),"W",WEEKNUM($C8,2)),"") -> 26W1 | C8: 46024 | D8: GEIL | E8: 44027 | F8: 2020-07-20 | G8: 45593 | H8: 28 | I8: 1000.68 | J8: =IFERROR(INDEX(ListaGestores!B:B,MATCH(D8,ListaGestores!A:A,0)),"Revisar Datos") -> JAVIERS
A9: =IF($C9<>"",_xlfn.CONCAT(MID(YEAR($C9),3,2),"M",MONTH($C9)),"") -> 26M1 | B9: =IF($C9<>"",_xlfn.CONCAT(MID(YEAR($C9),3,2),"W",WEEKNUM($C9,2)),"") -> 26W1 | C9: 46024 | D9: PLPC | E9: 44728 | F9: 2022-11-08 | G9: 45709 | H9: 8 | I9: 625.17 | J9: =IFERROR(INDEX(ListaGestores!B:B,MATCH(D9,ListaGestores!A:A,0)),"Revisar Datos") -> REINHART
A10: =IF($C10<>"",_xlfn.CONCAT(MID(YEAR($C10),3,2),"M",MONTH($C10)),"") -> 26M1 | B10: =IF($C10<>"",_xlfn.CONCAT(MID(YEAR($C10),3,2),"W",WEEKNUM($C10,2)),"") -> 26W1 | C10: 46024 | D10: Antec | E10: 45341 | F10: 2024-11-09 | G10: 45716 | H10: 17 | I10: 900.74 | J10: =IFERROR(INDEX(ListaGestores!B:B,MATCH(D10,ListaGestores!A:A,0)),"Revisar Datos") -> EMAA
A11: =IF($C11<>"",_xlfn.CONCAT(MID(YEAR($C11),3,2),"M",MONTH($C11)),"") -> 26M1 | B11: =IF($C11<>"",_xlfn.CONCAT(MID(YEAR($C11),3,2),"W",WEEKNUM($C11,2)),"") -> 26W1 | C11: 46024 | D11: Roitz | E11: 45246 | F11: 2024-09-06 | G11: 45750 | H11: 2 | I11: 283.78 | J11: =IFERROR(INDEX(ListaGestores!B:B,MATCH(D11,ListaGestores!A:A,0)),"Revisar Datos") -> 0
A12: =IF($C12<>"",_xlfn.CONCAT(MID(YEAR($C12),3,2),"M",MONTH($C12)),"") -> 26M1 | B12: =IF($C12<>"",_xlfn.CONCAT(MID(YEAR($C12),3,2),"W",WEEKNUM($C12,2)),"") -> 26W1 | C12: 46024 | D12: Intermaco | E12: 44973 | F12: 2023-09-27 | G12: 45756 | H12: 3 | I12: 181.1 | J12: =IFERROR(INDEX(ListaGestores!B:B,MATCH(D12,ListaGestores!A:A,0)),"Revisar Datos") -> JAVIERS
A13: =IF($C13<>"",_xlfn.CONCAT(MID(YEAR($C13),3,2),"M",MONTH($C13)),"") -> 26M1 | B13: =IF($C13<>"",_xlfn.CONCAT(MID(YEAR($C13),3,2),"W",WEEKNUM($C13,2)),"") -> 26W1 | C13: 46024 | D13: Siroco | E13: 45700 | F13: 2025-03-15 | G13: 45797 | H13: 2 | I13: 393.2 | J13: =IFERROR(INDEX(ListaGestores!B:B,MATCH(D13,ListaGestores!A:A,0)),"Revisar Datos") -> JAVIERS
... A196: =IF($C196<>"",_xlfn.CONCAT(MID(YEAR($C196),3,2),"M",MONTH($C196)),"") -> 26M1 | B196: =IF($C196<>"",_xlfn.CONCAT(MID(YEAR($C196),3,2),"W",WEEKNUM($C196,2)),"") -> 26W2 | C196: 46031 | D196: Patriot | E196: 44672 | F196: 2025-03-18 | G196: 46028 | H196: 1 | I196: 14.43 | J196: =IFERROR(INDEX(ListaGestores!B:B,MATCH(D196,ListaGestores!A:A,0)),"Revisar Datos") -> REINHART
A197: =IF($C197<>"",_xlfn.CONCAT(MID(YEAR($C197),3,2),"M",MONTH($C197)),"") -> 26M1 | B197: =IF($C197<>"",_xlfn.CONCAT(MID(YEAR($C197),3,2),"W",WEEKNUM($C197,2)),"") -> 26W2 | C197: 46031 | D197: Ashir | E197: 44673 | F197: 45995 | G197: 46029 | H197: 1 | I197: 36.14 | J197: =IFERROR(INDEX(ListaGestores!B:B,MATCH(D197,ListaGestores!A:A,0)),"Revisar Datos") -> ALANC
A198: =IF($C198<>"",_xlfn.CONCAT(MID(YEAR($C198),3,2),"M",MONTH($C198)),"") | B198: =IF($C198<>"",_xlfn.CONCAT(MID(YEAR($C198),3,2),"W",WEEKNUM($C198,2)),"") | J198: =IFERROR(INDEX(ListaGestores!B:B,MATCH(D198,ListaGestores!A:A,0)),"Revisar Datos") -> Revisar Datos
A199: =IF($C199<>"",_xlfn.CONCAT(MID(YEAR($C199),3,2),"M",MONTH($C199)),"") | B199: =IF($C199<>"",_xlfn.CONCAT(MID(YEAR($C199),3,2),"W",WEEKNUM($C199,2)),"") | J199: =IFERROR(INDEX(ListaGestores!B:B,MATCH(D199,ListaGestores!A:A,0)),"Revisar Datos") -> Revisar Datos
A200: =IF($C200<>"",_xlfn.CONCAT(MID(YEAR($C200),3,2),"M",MONTH($C200)),"") | B200: =IF($C200<>"",_xlfn.CONCAT(MID(YEAR($C200),3,2),"W",WEEKNUM($C200,2)),"") | J200: =IFERROR(INDEX(ListaGestores!B:B,MATCH(D200,ListaGestores!A:A,0)),"Revisar Datos") -> Revisar Datos
A201: =IF($C201<>"",_xlfn.CONCAT(MID(YEAR($C201),3,2),"M",MONTH($C201)),"") | B201: =IF($C201<>"",_xlfn.CONCAT(MID(YEAR($C201),3,2),"W",WEEKNUM($C201,2)),"") | J201: =IFERROR(INDEX(ListaGestores!B:B,MATCH(D201,ListaGestores!A:A,0)),"Revisar Datos") -> Revisar Datos
A202: =IF($C202<>"",_xlfn.CONCAT(MID(YEAR($C202),3,2),"M",MONTH($C202)),"") | B202: =IF($C202<>"",_xlfn.CONCAT(MID(YEAR($C202),3,2),"W",WEEKNUM($C202,2)),"") | J202: =IFERROR(INDEX(ListaGestores!B:B,MATCH(D202,ListaGestores!A:A,0)),"Revisar Datos") -> Revisar Datos
A203: =IF($C203<>"",_xlfn.CONCAT(MID(YEAR($C203),3,2),"M",MONTH($C203)),"") | B203: =IF($C203<>"",_xlfn.CONCAT(MID(YEAR($C203),3,2),"W",WEEKNUM($C203,2)),"") | J203: =IFERROR(INDEX(ListaGestores!B:B,MATCH(D203,ListaGestores!A:A,0)),"Revisar Datos") -> Revisar Datos
A204: =IF($C204<>"",_xlfn.CONCAT(MID(YEAR($C204),3,2),"M",MONTH($C204)),"") | B204: =IF($C204<>"",_xlfn.CONCAT(MID(YEAR($C204),3,2),"W",WEEKNUM($C204,2)),"") | J204: =IFERROR(INDEX(ListaGestores!B:B,MATCH(D204,ListaGestores!A:A,0)),"Revisar Datos") -> Revisar Datos
A205: =IF($C205<>"",_xlfn.CONCAT(MID(YEAR($C205),3,2),"M",MONTH($C205)),"") | B205: =IF($C205<>"",_xlfn.CONCAT(MID(YEAR($C205),3,2),"W",WEEKNUM($C205,2)),"") | J205: =IFERROR(INDEX(ListaGestores!B:B,MATCH(D205,ListaGestores!A:A,0)),"Revisar Datos") -> Revisar Datos
A206: =IF($C206<>"",_xlfn.CONCAT(MID(YEAR($C206),3,2),"M",MONTH($C206)),"") | B206: =IF($C206<>"",_xlfn.CONCAT(MID(YEAR($C206),3,2),"W",WEEKNUM($C206,2)),"") | J206: =IFERROR(INDEX(ListaGestores!B:B,MATCH(D206,ListaGestores!A:A,0)),"Revisar Datos") -> Revisar Datos
A207: =IF($C207<>"",_xlfn.CONCAT(MID(YEAR($C207),3,2),"M",MONTH($C207)),"") | B207: =IF($C207<>"",_xlfn.CONCAT(MID(YEAR($C207),3,2),"W",WEEKNUM($C207,2)),"") | J207: =IFERROR(INDEX(ListaGestores!B:B,MATCH(D207,ListaGestores!A:A,0)),"Revisar Datos") -> Revisar Datos
A208: =IF($C208<>"",_xlfn.CONCAT(MID(YEAR($C208),3,2),"M",MONTH($C208)),"") | B208: =IF($C208<>"",_xlfn.CONCAT(MID(YEAR($C208),3,2),"W",WEEKNUM($C208,2)),"") | J208: =IFERROR(INDEX(ListaGestores!B:B,MATCH(D208,ListaGestores!A:A,0)),"Revisar Datos") -> Revisar Datos
A209: =IF($C209<>"",_xlfn.CONCAT(MID(YEAR($C209),3,2),"M",MONTH($C209)),"") | B209: =IF($C209<>"",_xlfn.CONCAT(MID(YEAR($C209),3,2),"W",WEEKNUM($C209,2)),"") | J209: =IFERROR(INDEX(ListaGestores!B:B,MATCH(D209,ListaGestores!A:A,0)),"Revisar Datos") -> Revisar Datos
... A3838: =IF($C3838<>"",_xlfn.CONCAT(MID(YEAR($C3838),3,2),"M",MONTH($C3838)),"") | B3838: =IF($C3838<>"",_xlfn.CONCAT(MID(YEAR($C3838),3,2),"W",WEEKNUM($C3838,2)),"") | J3838: =IFERROR(INDEX(ListaGestores!B:B,MATCH(D3838,ListaGestores!A:A,0)),"Revisar Datos") -> Revisar Datos

Sheet Bruto CambiosEstado
A1: MES | B1: SEMANA | C1: FECHA | D1: ID_ESTADO | E1: ESTADO | F1: ALANC | G1: EMAA | H1: JAVIERS | I1: MATIASNG | J1: REINHART
A2: =IF($C2<>"",_xlfn.CONCAT(MID(YEAR($C2),3,2),"M",MONTH($C2)),"") -> 26M1 | B2: =IF($C2<>"",_xlfn.CONCAT(MID(YEAR($C2),3,2),"W",WEEKNUM($C2,2)),"") -> 26W1 | C2: 46024 | D2: 1 | E2: Pendiente de confirmación | F2: 0 | G2: 2 | H2: 0 | I2: 0 | J2: 1
A3: =IF($C3<>"",_xlfn.CONCAT(MID(YEAR($C3),3,2),"M",MONTH($C3)),"") -> 26M1 | B3: =IF($C3<>"",_xlfn.CONCAT(MID(YEAR($C3),3,2),"W",WEEKNUM($C3,2)),"") -> 26W1 | C3: 46024 | D3: 2 | E3: Pendiente de gestión | F3: 16 | G3: 14 | H3: 8 | I3: 34 | J3: 25
A4: =IF($C4<>"",_xlfn.CONCAT(MID(YEAR($C4),3,2),"M",MONTH($C4)),"") -> 26M1 | B4: =IF($C4<>"",_xlfn.CONCAT(MID(YEAR($C4),3,2),"W",WEEKNUM($C4,2)),"") -> 26W1 | C4: 46024 | D4: 3 | E4: Gestión en proceso | F4: 10 | G4: 0 | H4: 3 | I4: 74 | J4: 0
A5: =IF($C5<>"",_xlfn.CONCAT(MID(YEAR($C5),3,2),"M",MONTH($C5)),"") -> 26M1 | B5: =IF($C5<>"",_xlfn.CONCAT(MID(YEAR($C5),3,2),"W",WEEKNUM($C5,2)),"") -> 26W1 | C5: 46024 | D5: 4 | E5: Pendiente para despachar | F5: 8 | G5: 0 | H5: 1 | I5: 0 | J5: 0
A6: =IF($C6<>"",_xlfn.CONCAT(MID(YEAR($C6),3,2),"M",MONTH($C6)),"") -> 26M1 | B6: =IF($C6<>"",_xlfn.CONCAT(MID(YEAR($C6),3,2),"W",WEEKNUM($C6,2)),"") -> 26W1 | C6: 46024 | D6: 5 | E6: Listo para despachar | F6: 7 | G6: 0 | H6: 13 | I6: 0 | J6: 0
A7: =IF($C7<>"",_xlfn.CONCAT(MID(YEAR($C7),3,2),"M",MONTH($C7)),"") -> 26M1 | B7: =IF($C7<>"",_xlfn.CONCAT(MID(YEAR($C7),3,2),"W",WEEKNUM($C7,2)),"") -> 26W1 | C7: 46024 | D7: 6 | E7: Resolución pendiente | F7: 7 | G7: 0 | H7: 24 | I7: 0 | J7: 0
A8: =IF($C8<>"",_xlfn.CONCAT(MID(YEAR($C8),3,2),"M",MONTH($C8)),"") -> 26M1 | B8: =IF($C8<>"",_xlfn.CONCAT(MID(YEAR($C8),3,2),"W",WEEKNUM($C8,2)),"") -> 26W1 | C8: 46024 | D8: 7 | E8: Producto por 1% | F8: 0 | G8: 0 | H8: 6 | I8: 0 | J8: 0
A9: =IF($C9<>"",_xlfn.CONCAT(MID(YEAR($C9),3,2),"M",MONTH($C9)),"") -> 26M1 | B9: =IF($C9<>"",_xlfn.CONCAT(MID(YEAR($C9),3,2),"W",WEEKNUM($C9,2)),"") -> 26W1 | C9: 46024 | D9: 8 | E9: Cambio por producto nuevo | F9: 0 | G9: 0 | H9: 0 | I9: 0 | J9: 0
A10: =IF($C10<>"",_xlfn.CONCAT(MID(YEAR($C10),3,2),"M",MONTH($C10)),"") -> 26M1 | B10: =IF($C10<>"",_xlfn.CONCAT(MID(YEAR($C10),3,2),"W",WEEKNUM($C10,2)),"") -> 26W1 | C10: 46024 | D10: 9 | E10: Cambio por producto reacondicionado | F10: 0 | G10: 0 | H10: 0 | I10: 0 | J10: 0
A11: =IF($C11<>"",_xlfn.CONCAT(MID(YEAR($C11),3,2),"M",MONTH($C11)),"") -> 26M1 | B11: =IF($C11<>"",_xlfn.CONCAT(MID(YEAR($C11),3,2),"W",WEEKNUM($C11,2)),"") -> 26W1 | C11: 46024 | D11: 10 | E11: Producto reparado | F11: 0 | G11: 0 | H11: 0 | I11: 0 | J11: 0
A12: =IF($C12<>"",_xlfn.CONCAT(MID(YEAR($C12),3,2),"M",MONTH($C12)),"") -> 26M1 | B12: =IF($C12<>"",_xlfn.CONCAT(MID(YEAR($C12),3,2),"W",WEEKNUM($C12,2)),"") -> 26W1 | C12: 46024 | D12: 11 | E12: Nota de credito | F12: 0 | G12: 5 | H12: 0 | I12: 0 | J12: 0
A13: =IF($C13<>"",_xlfn.CONCAT(MID(YEAR($C13),3,2),"M",MONTH($C13)),"") -> 26M1 | B13: =IF($C13<>"",_xlfn.CONCAT(MID(YEAR($C13),3,2),"W",WEEKNUM($C13,2)),"") -> 26W1 | C13: 46024 | D13: 12 | E13: Acuerdo comercial | F13: 0 | G13: 0 | H13: 0 | I13: 0 | J13: 0
... A55: =IF($C55<>"",_xlfn.CONCAT(MID(YEAR($C55),3,2),"M",MONTH($C55)),"") -> 26M1 | B55: =IF($C55<>"",_xlfn.CONCAT(MID(YEAR($C55),3,2),"W",WEEKNUM($C55,2)),"") -> 26W2 | C55: 46031 | D55: 18 | E55: Falso diagnóstico por Gestor | F55: 0 | G55: 0 | H55: 0 | I55: 0 | J55: 0
A56: =IF($C56<>"",_xlfn.CONCAT(MID(YEAR($C56),3,2),"M",MONTH($C56)),"") | B56: =IF($C56<>"",_xlfn.CONCAT(MID(YEAR($C56),3,2),"W",WEEKNUM($C56,2)),"")
A57: =IF($C57<>"",_xlfn.CONCAT(MID(YEAR($C57),3,2),"M",MONTH($C57)),"") | B57: =IF($C57<>"",_xlfn.CONCAT(MID(YEAR($C57),3,2),"W",WEEKNUM($C57,2)),"")
A58: =IF($C58<>"",_xlfn.CONCAT(MID(YEAR($C58),3,2),"M",MONTH($C58)),"") | B58: =IF($C58<>"",_xlfn.CONCAT(MID(YEAR($C58),3,2),"W",WEEKNUM($C58,2)),"")
A59: =IF($C59<>"",_xlfn.CONCAT(MID(YEAR($C59),3,2),"M",MONTH($C59)),"") | B59: =IF($C59<>"",_xlfn.CONCAT(MID(YEAR($C59),3,2),"W",WEEKNUM($C59,2)),"")
A60: =IF($C60<>"",_xlfn.CONCAT(MID(YEAR($C60),3,2),"M",MONTH($C60)),"") | B60: =IF($C60<>"",_xlfn.CONCAT(MID(YEAR($C60),3,2),"W",WEEKNUM($C60,2)),"")
A61: =IF($C61<>"",_xlfn.CONCAT(MID(YEAR($C61),3,2),"M",MONTH($C61)),"") | B61: =IF($C61<>"",_xlfn.CONCAT(MID(YEAR($C61),3,2),"W",WEEKNUM($C61,2)),"")
A62: =IF($C62<>"",_xlfn.CONCAT(MID(YEAR($C62),3,2),"M",MONTH($C62)),"") | B62: =IF($C62<>"",_xlfn.CONCAT(MID(YEAR($C62),3,2),"W",WEEKNUM($C62,2)),"")
A63: =IF($C63<>"",_xlfn.CONCAT(MID(YEAR($C63),3,2),"M",MONTH($C63)),"") | B63: =IF($C63<>"",_xlfn.CONCAT(MID(YEAR($C63),3,2),"W",WEEKNUM($C63,2)),"")
A64: =IF($C64<>"",_xlfn.CONCAT(MID(YEAR($C64),3,2),"M",MONTH($C64)),"") | B64: =IF($C64<>"",_xlfn.CONCAT(MID(YEAR($C64),3,2),"W",WEEKNUM($C64,2)),"")
A65: =IF($C65<>"",_xlfn.CONCAT(MID(YEAR($C65),3,2),"M",MONTH($C65)),"") | B65: =IF($C65<>"",_xlfn.CONCAT(MID(YEAR($C65),3,2),"W",WEEKNUM($C65,2)),"")
A66: =IF($C66<>"",_xlfn.CONCAT(MID(YEAR($C66),3,2),"M",MONTH($C66)),"") | B66: =IF($C66<>"",_xlfn.CONCAT(MID(YEAR($C66),3,2),"W",WEEKNUM($C66,2)),"")
A67: =IF($C67<>"",_xlfn.CONCAT(MID(YEAR($C67),3,2),"M",MONTH($C67)),"") | B67: =IF($C67<>"",_xlfn.CONCAT(MID(YEAR($C67),3,2),"W",WEEKNUM($C67,2)),"")
... A2999: =IF($C2999<>"",_xlfn.CONCAT(MID(YEAR($C2999),3,2),"M",MONTH($C2999)),"") | B2999: =IF($C2999<>"",_xlfn.CONCAT(MID(YEAR($C2999),3,2),"W",WEEKNUM($C2999,2)),"")
A3000: =IF($C3000<>"",_xlfn.CONCAT(MID(YEAR($C3000),3,2),"M",MONTH($C3000)),"") -> #VALUE! | B3000: =IF($C3000<>"",_xlfn.CONCAT(MID(YEAR($C3000),3,2),"W",WEEKNUM($C3000,2)),"") -> #VALUE! | C3000: LIMITE TEORICO | E3000: LIMITE TEORICO | F3000: LIMITE TEORICO | G3000: LIMITE TEORICO | H3000: LIMITE TEORICO | I3000: LIMITE TEORICO | J3000: LIMITE TEORICO | K3000: LIMITE TEORICO

Sheet CambiosEstado
B3: Valores | C3: SEMANA | P3: ESTADO | Q3: AGENTE | AA3: GENERAL
B4: ID ESTADO | D4: Suma de ALANC | F4: Suma de EMAA | H4: Suma de JAVIERS | J4: Suma de MATIASNG | L4: Suma de REINHART | Q4: ALANC | S4: EMAA | U4: JAVIERS | W4: MATIASNG | Y4: REINHART
A5: ESTADO | B5: 26W1 | C5: 26W2 | D5: 26W1 | E5: 26W2 | F5: 26W1 | G5: 26W2 | H5: 26W1 | I5: 26W2 | J5: 26W1 | K5: 26W2 | L5: 26W1 | M5: 26W2 | Q5: =D5 -> 26W1 | R5: =E5 -> 26W2 | S5: =F5 -> 26W1 | T5: =G5 -> 26W2 | U5: =H5 -> 26W1 | V5: =I5 -> 26W2 | W5: =J5 -> 26W1 | X5: =K5 -> 26W2 | ... Z5: =M5 -> 26W2 | AA5: =B5 -> 26W1 | AB5: =C5 -> 26W2
A6: Pendiente de confirmación | B6: 1 | C6: 1 | D6: 0 | E6: 4 | F6: 2 | G6: 0 | H6: 0 | I6: 0 | J6: 0 | K6: 0 | L6: 1 | M6: 2 | P6: Pendiente de confirmación | Q6: =D6 -> 0 | R6: =E6 -> 4 | S6: =F6 -> 2 | T6: =G6 -> 0 | U6: =H6 -> 0 | V6: =I6 -> 0 | W6: =J6 -> 0 | X6: =K6 -> 0 | ... Z6: =M6 -> 2 | AA6: =Q6+S6+U6+W6+Y6 -> 3 | AB6: =R6+T6+V6+X6+Z6 -> 6
A7: Pendiente de gestión | B7: 2 | C7: 2 | D7: 16 | E7: 43 | F7: 14 | G7: 0 | H7: 8 | I7: 12 | J7: 34 | K7: 15 | L7: 25 | M7: 15 | P7: Pendiente de gestión | Q7: =D7 -> 16 | R7: =E7 -> 43 | S7: =F7 -> 14 | T7: =G7 -> 0 | U7: =H7 -> 8 | V7: =I7 -> 12 | W7: =J7 -> 34 | X7: =K7 -> 15 | ... Z7: =M7 -> 15 | AA7: =Q7+S7+U7+W7+Y7 -> 97 | AB7: =R7+T7+V7+X7+Z7 -> 85
A8: Gestión en proceso | B8: 3 | C8: 3 | D8: 10 | E8: 0 | F8: 0 | G8: 0 | H8: 3 | I8: 34 | J8: 74 | K8: 5 | L8: 0 | M8: 44 | P8: Gestión en proceso | Q8: =D8 -> 10 | R8: =E8 -> 0 | S8: =F8 -> 0 | T8: =G8 -> 0 | U8: =H8 -> 3 | V8: =I8 -> 34 | W8: =J8 -> 74 | X8: =K8 -> 5 | ... Z8: =M8 -> 44 | AA8: =Q8+S8+U8+W8+Y8 -> 87 | AB8: =R8+T8+V8+X8+Z8 -> 83
A9: Pendiente para despachar | B9: 4 | C9: 4 | D9: 8 | E9: 8 | F9: 0 | G9: 0 | H9: 1 | I9: 0 | J9: 0 | K9: 5 | L9: 0 | M9: 0 | P9: Pendiente para despachar | Q9: =D9 -> 8 | R9: =E9 -> 8 | S9: =F9 -> 0 | T9: =G9 -> 0 | U9: =H9 -> 1 | V9: =I9 -> 0 | W9: =J9 -> 0 | X9: =K9 -> 5 | ... Z9: =M9 -> 0 | AA9: =Q9+S9+U9+W9+Y9 -> 9 | AB9: =R9+T9+V9+X9+Z9 -> 13
A10: Listo para despachar | B10: 5 | C10: 5 | D10: 7 | E10: 8 | F10: 0 | G10: 0 | H10: 13 | I10: 0 | J10: 0 | K10: 3 | L10: 0 | M10: 0 | P10: Listo para despachar | Q10: =D10 -> 7 | R10: =E10 -> 8 | S10: =F10 -> 0 | T10: =G10 -> 0 | U10: =H10 -> 13 | V10: =I10 -> 0 | W10: =J10 -> 0 | X10: =K10 -> 3 | ... Z10: =M10 -> 0 | AA10: =Q10+S10+U10+W10+Y10 -> 20 | AB10: =R10+T10+V10+X10+Z10 -> 11
A11: Resolución pendiente | B11: 6 | C11: 6 | D11: 7 | E11: 8 | F11: 0 | G11: 0 | H11: 24 | I11: 0 | J11: 0 | K11: 3 | L11: 0 | M11: 34 | P11: Resolución pendiente | Q11: =D11 -> 7 | R11: =E11 -> 8 | S11: =F11 -> 0 | T11: =G11 -> 0 | U11: =H11 -> 24 | V11: =I11 -> 0 | W11: =J11 -> 0 | X11: =K11 -> 3 | ... Z11: =M11 -> 34 | AA11: =Q11+S11+U11+W11+Y11 -> 31 | AB11: =R11+T11+V11+X11+Z11 -> 45
A12: Producto por 1% | B12: 7 | C12: 7 | D12: 0 | E12: 0 | F12: 0 | G12: 0 | H12: 6 | I12: 0 | J12: 0 | K12: 0 | L12: 0 | M12: 34 | P12: Producto por 1% | Q12: =D12 -> 0 | R12: =E12 -> 0 | S12: =F12 -> 0 | T12: =G12 -> 0 | U12: =H12 -> 6 | V12: =I12 -> 0 | W12: =J12 -> 0 | X12: =K12 -> 0 | ... Z12: =M12 -> 34 | AA12: =Q12+S12+U12+W12+Y12 -> 6 | AB12: =R12+T12+V12+X12+Z12 -> 34
A13: Cambio por producto nuevo | B13: 8 | C13: 8 | D13: 0 | E13: 17 | F13: 0 | G13: 0 | H13: 0 | I13: 0 | J13: 0 | K13: 0 | L13: 0 | M13: 6 | P13: Cambio por producto nuevo | Q13: =D13 -> 0 | R13: =E13 -> 17 | S13: =F13 -> 0 | T13: =G13 -> 0 | U13: =H13 -> 0 | V13: =I13 -> 0 | W13: =J13 -> 0 | X13: =K13 -> 0 | ... Z13: =M13 -> 6 | AA13: =Q13+S13+U13+W13+Y13 -> 0 | AB13: =R13+T13+V13+X13+Z13 -> 23
A14: Cambio por producto reacondicionado | B14: 9 | C14: 9 | D14: 0 | E14: 0 | F14: 0 | G14: 0 | H14: 0 | I14: 0 | J14: 0 | K14: 0 | L14: 0 | M14: 0 | P14: Cambio por producto reacondicionado | Q14: =D14 -> 0 | R14: =E14 -> 0 | S14: =F14 -> 0 | T14: =G14 -> 0 | U14: =H14 -> 0 | V14: =I14 -> 0 | W14: =J14 -> 0 | X14: =K14 -> 0 | ... Z14: =M14 -> 0 | AA14: =Q14+S14+U14+W14+Y14 -> 0 | AB14: =R14+T14+V14+X14+Z14 -> 0
A15: Producto reparado | B15: 10 | C15: 10 | D15: 0 | E15: 0 | F15: 0 | G15: 0 | H15: 0 | I15: 0 | J15: 0 | K15: 0 | L15: 0 | M15: 0 | P15: Producto reparado | Q15: =D15 -> 0 | R15: =E15 -> 0 | S15: =F15 -> 0 | T15: =G15 -> 0 | U15: =H15 -> 0 | V15: =I15 -> 0 | W15: =J15 -> 0 | X15: =K15 -> 0 | ... Z15: =M15 -> 0 | AA15: =Q15+S15+U15+W15+Y15 -> 0 | AB15: =R15+T15+V15+X15+Z15 -> 0
A16: Nota de credito | B16: 11 | C16: 11 | D16: 0 | E16: 0 | F16: 5 | G16: 0 | H16: 0 | I16: 0 | J16: 0 | K16: 53 | L16: 0 | M16: 16 | P16: Nota de credito | Q16: =D16 -> 0 | R16: =E16 -> 0 | S16: =F16 -> 5 | T16: =G16 -> 0 | U16: =H16 -> 0 | V16: =I16 -> 0 | W16: =J16 -> 0 | X16: =K16 -> 53 | ... Z16: =M16 -> 16 | AA16: =Q16+S16+U16+W16+Y16 -> 5 | AB16: =R16+T16+V16+X16+Z16 -> 69
A17: Acuerdo comercial | B17: 12 | C17: 12 | D17: 0 | E17: 0 | F17: 0 | G17: 0 | H17: 0 | I17: 0 | J17: 0 | K17: 0 | L17: 0 | M17: 0 | P17: Acuerdo comercial | Q17: =D17 -> 0 | R17: =E17 -> 0 | S17: =F17 -> 0 | T17: =G17 -> 0 | U17: =H17 -> 0 | V17: =I17 -> 0 | W17: =J17 -> 0 | X17: =K17 -> 0 | ... Z17: =M17 -> 0 | AA17: =Q17+S17+U17+W17+Y17 -> 0 | AB17: =R17+T17+V17+X17+Z17 -> 0
... A23: Falso diagnóstico por Gestor | B23: 18 | C23: 18 | D23: 0 | E23: 0 | F23: 3 | G23: 0 | H23: 0 | I23: 0 | J23: 0 | K23: 0 | L23: 0 | M23: 0 | P23: Falso diagnóstico por Gestor | Q23: =D23 -> 0 | R23: =E23 -> 0 | S23: =F23 -> 3 | T23: =G23 -> 0 | U23: =H23 -> 0 | V23: =I23 -> 0 | W23: =J23 -> 0 | X23: =K23 -> 0 | ... Z23: =M23 -> 0 | AA23: =Q23+S23+U23+W23+Y23 -> 3 | AB23: =R23+T23+V23+X23+Z23 -> 0
P24: TOTALES | Q24: =SUM(Q6:Q23) -> 48 | R24: =SUM(R6:R23) -> 93 | S24: =SUM(S6:S23) -> 24 | T24: =SUM(T6:T23) -> 0 | U24: =SUM(U6:U23) -> 60 | V24: =SUM(V6:V23) -> 49 | W24: =SUM(W6:W23) -> 108 | X24: =SUM(X6:X23) -> 88 | ... AB24: =SUM(AB6:AB23) -> 381

Sheet Gestores ALANC
A1: AGENTE | B1: ALANC
B3: SEMANA | C3: Valores
B4: 26W1 | E4: 26W2 | I4: GESTOR | J4: =B4 -> 26W1 | K4: =B4 -> 26W1 | M4: =E4 -> 26W2 | N4: =E4 -> 26W2
A5: GESTOR | B5: Monto Pendiente | C5: Unidades Pendientes | D5: Fecha de Compra | E5: Monto Pendiente | F5: Unidades Pendientes | G5: Fecha de Compra | J5: MONTO PENDIENTE | K5: UNIDADES PENDIENTES | L5: FECHA DE COMPRA | M5: MONTO PENDIENTE | N5: UNIDADES PENDIENTES | O5: FECHA DE COMPRA
A6: Ashir | E6: 36.14 | F6: 1 | G6: 44673 | I6: =IF(A6=0,"",A6) -> Ashir | J6: =IF(B6=0,"",B6) | K6: =IF(C6=0,"",C6) | L6: =IF(D6=0,"",D6) | M6: =IF(E6=0,"",E6) -> 36.14 | N6: =IF(F6=0,"",F6) -> 1 | O6: =IF(G6=0,"",G6) -> 44673
A7: Be Quiet! | B7: 879.37 | C7: 11 | D7: 44617 | E7: 956.1 | F7: 12 | G7: 44617 | I7: =IF(A7=0,"",A7) -> Be Quiet! | J7: =IF(B7=0,"",B7) -> 879.37 | K7: =IF(C7=0,"",C7) -> 11 | L7: =IF(D7=0,"",D7) -> 44617 | M7: =IF(E7=0,"",E7) -> 956.1 | N7: =IF(F7=0,"",F7) -> 12 | O7: =IF(G7=0,"",G7) -> 44617
A8: Corcisa | B8: 25.3 | C8: 1 | D8: 45791 | E8: 25.3 | F8: 1 | G8: 44665 | I8: =IF(A8=0,"",A8) -> Corcisa | J8: =IF(B8=0,"",B8) -> 25.3 | K8: =IF(C8=0,"",C8) -> 1 | L8: =IF(D8=0,"",D8) -> 45791 | M8: =IF(E8=0,"",E8) -> 25.3 | N8: =IF(F8=0,"",F8) -> 1 | O8: =IF(G8=0,"",G8) -> 44665
A9: Dahua | B9: 173.89 | C9: 3 | D9: 45911 | E9: 337.52 | F9: 6 | G9: 44661 | I9: =IF(A9=0,"",A9) -> Dahua | J9: =IF(B9=0,"",B9) -> 173.89 | K9: =IF(C9=0,"",C9) -> 3 | L9: =IF(D9=0,"",D9) -> 45911 | M9: =IF(E9=0,"",E9) -> 337.52 | N9: =IF(F9=0,"",F9) -> 6 | O9: =IF(G9=0,"",G9) -> 44661
A10: Deepcool Beijing | B10: 994.83 | C10: 16 | D10: 45797 | E10: 1050.76 | F10: 18 | G10: 45797 | I10: =IF(A10=0,"",A10) -> Deepcool Beijing | J10: =IF(B10=0,"",B10) -> 994.83 | K10: =IF(C10=0,"",C10) -> 16 | L10: =IF(D10=0,"",D10) -> 45797 | M10: =IF(E10=0,"",E10) -> 1050.76 | N10: =IF(F10=0,"",F10) -> 18 | O10: =IF(G10=0,"",G10) -> 45797
A11: Elit | B11: 303.55 | C11: 3 | D11: 45728 | E11: 303.55 | F11: 3 | G11: 44659 | I11: =IF(A11=0,"",A11) -> Elit | J11: =IF(B11=0,"",B11) -> 303.55 | K11: =IF(C11=0,"",C11) -> 3 | L11: =IF(D11=0,"",D11) -> 45728 | M11: =IF(E11=0,"",E11) -> 303.55 | N11: =IF(F11=0,"",F11) -> 3 | O11: =IF(G11=0,"",G11) -> 44659
A12: Grupo Núcleo | B12: 625.01 | C12: 4 | D12: 44973 | E12: 625.01 | F12: 4 | G12: 44973 | I12: =IF(A12=0,"",A12) -> Grupo Núcleo | J12: =IF(B12=0,"",B12) -> 625.01 | K12: =IF(C12=0,"",C12) -> 4 | L12: =IF(D12=0,"",D12) -> 44973 | M12: =IF(E12=0,"",E12) -> 625.01 | N12: =IF(F12=0,"",F12) -> 4 | O12: =IF(G12=0,"",G12) -> 44973
A13: IT Brokers | B13: 7.78 | C13: 1 | D13: 45042 | E13: 7.78 | F13: 1 | G13: 45042 | I13: =IF(A13=0,"",A13) -> IT Brokers | J13: =IF(B13=0,"",B13) -> 7.78 | K13: =IF(C13=0,"",C13) -> 1 | L13: =IF(D13=0,"",D13) -> 45042 | M13: =IF(E13=0,"",E13) -> 7.78 | N13: =IF(F13=0,"",F13) -> 1 | O13: =IF(G13=0,"",G13) -> 45042
A14: Latamly | B14: 449.85 | C14: 16 | D14: 45608 | E14: 543.69 | F14: 19 | G14: 45608 | I14: =IF(A14=0,"",A14) -> Latamly | J14: =IF(B14=0,"",B14) -> 449.85 | K14: =IF(C14=0,"",C14) -> 16 | L14: =IF(D14=0,"",D14) -> 45608 | M14: =IF(E14=0,"",E14) -> 543.69 | N14: =IF(F14=0,"",F14) -> 19 | O14: =IF(G14=0,"",G14) -> 45608
A15: Seagate - Prexey | B15: 185.09 | C15: 2 | D15: 45736 | E15: 185.09 | F15: 2 | G15: 44664 | I15: =IF(A15=0,"",A15) -> Seagate - Prexey | J15: =IF(B15=0,"",B15) -> 185.09 | K15: =IF(C15=0,"",C15) -> 2 | L15: =IF(D15=0,"",D15) -> 45736 | M15: =IF(E15=0,"",E15) -> 185.09 | N15: =IF(F15=0,"",F15) -> 2 | O15: =IF(G15=0,"",G15) -> 44664
A16: Western Digital - Vortex | B16: 1227.86 | C16: 18 | D16: 44753 | E16: 1264.36 | F16: 19 | G16: 44753 | I16: =IF(A16=0,"",A16) -> Western Digital - Vortex | J16: =IF(B16=0,"",B16) -> 1227.86 | K16: =IF(C16=0,"",C16) -> 18 | L16: =IF(D16=0,"",D16) -> 44753 | M16: =IF(E16=0,"",E16) -> 1264.36 | N16: =IF(F16=0,"",F16) -> 19 | O16: =IF(G16=0,"",G16) -> 44753
A17: XYZ | B17: 426.23 | C17: 12 | D17: 45721 | E17: 577.14 | F17: 14 | G17: 45721 | I17: =IF(A17=0,"",A17) -> XYZ | J17: =IF(B17=0,"",B17) -> 426.23 | K17: =IF(C17=0,"",C17) -> 12 | L17: =IF(D17=0,"",D17) -> 45721 | M17: =IF(E17=0,"",E17) -> 577.14 | N17: =IF(F17=0,"",F17) -> 14 | O17: =IF(G17=0,"",G17) -> 45721
I18: =IF(A18=0,"",A18) | J18: =IF(B18=0,"",B18) | K18: =IF(C18=0,"",C18) | L18: =IF(D18=0,"",D18) | M18: =IF(E18=0,"",E18) | N18: =IF(F18=0,"",F18) | O18: =IF(G18=0,"",G18)
I19: =IF(A19=0,"",A19) | J19: =IF(B19=0,"",B19) | K19: =IF(C19=0,"",C19) | L19: =IF(D19=0,"",D19) | M19: =IF(E19=0,"",E19) | N19: =IF(F19=0,"",F19) | O19: =IF(G19=0,"",G19)
I20: =IF(A20=0,"",A20) | J20: =IF(B20=0,"",B20) | K20: =IF(C20=0,"",C20) | L20: =IF(D20=0,"",D20) | M20: =IF(E20=0,"",E20) | N20: =IF(F20=0,"",F20) | O20: =IF(G20=0,"",G20)
I21: =IF(A21=0,"",A21) | J21: =IF(B21=0,"",B21) | K21: =IF(C21=0,"",C21) | L21: =IF(D21=0,"",D21) | M21: =IF(E21=0,"",E21) | N21: =IF(F21=0,"",F21) | O21: =IF(G21=0,"",G21)
I22: =IF(A22=0,"",A22) | J22: =IF(B22=0,"",B22) | K22: =IF(C22=0,"",C22) | L22: =IF(D22=0,"",D22) | M22: =IF(E22=0,"",E22) | N22: =IF(F22=0,"",F22) | O22: =IF(G22=0,"",G22)
I23: =IF(A23=0,"",A23) | J23: =IF(B23=0,"",B23) | K23: =IF(C23=0,"",C23) | L23: =IF(D23=0,"",D23) | M23: =IF(E23=0,"",E23) | N23: =IF(F23=0,"",F23) | O23: =IF(G23=0,"",G23)
I24: =IF(A24=0,"",A24) | J24: =IF(B24=0,"",B24) | K24: =IF(C24=0,"",C24) | L24: =IF(D24=0,"",D24) | M24: =IF(E24=0,"",E24) | N24: =IF(F24=0,"",F24) | O24: =IF(G24=0,"",G24)
I25: =IF(A25=0,"",A25) | J25: =IF(B25=0,"",B25) | K25: =IF(C25=0,"",C25) | L25: =IF(D25=0,"",D25) | M25: =IF(E25=0,"",E25) | N25: =IF(F25=0,"",F25) | O25: =IF(G25=0,"",G25)
I26: =IF(A26=0,"",A26) | J26: =IF(B26=0,"",B26) | K26: =IF(C26=0,"",C26) | L26: =IF(D26=0,"",D26) | M26: =IF(E26=0,"",E26) | N26: =IF(F26=0,"",F26) | O26: =IF(G26=0,"",G26)

Sheet Gestores EMAA
A1: AGENTE | B1: EMAA
B3: SEMANA | C3: Valores
B4: 26W1 | E4: 26W2 | I4: GESTOR | J4: =B4 -> 26W1 | K4: =B4 -> 26W1 | M4: =E4 -> 26W2 | N4: =E4 -> 26W2
A5: GESTOR | B5: Monto Pendiente | C5: Unidades Pendientes | D5: Fecha de Compra | E5: Monto Pendiente | F5: Unidades Pendientes | G5: Fecha de Compra | J5: MONTO PENDIENTE | K5: UNIDADES PENDIENTES | L5: FECHA DE COMPRA | M5: MONTO PENDIENTE | N5: UNIDADES PENDIENTES | O5: FECHA DE COMPRA
A6: Acer - Techcom | B6: 1366.99 | C6: 6 | D6: 45679 | E6: 1425.97 | F6: 7 | G6: 45679 | I6: =IF(A6=0,"",A6) -> Acer - Techcom | J6: =IF(B6=0,"",B6) -> 1366.99 | K6: =IF(C6=0,"",C6) -> 6 | L6: =IF(D6=0,"",D6) -> 45679 | M6: =IF(E6=0,"",E6) -> 1425.97 | N6: =IF(F6=0,"",F6) -> 7 | O6: =IF(G6=0,"",G6) -> 45679
A7: AIR | B7: 677.85 | C7: 10 | D7: 44749 | E7: 677.85 | F7: 10 | G7: 44749 | I7: =IF(A7=0,"",A7) -> AIR | J7: =IF(B7=0,"",B7) -> 677.85 | K7: =IF(C7=0,"",C7) -> 10 | L7: =IF(D7=0,"",D7) -> 44749 | M7: =IF(E7=0,"",E7) -> 677.85 | N7: =IF(F7=0,"",F7) -> 10 | O7: =IF(G7=0,"",G7) -> 44749
A8: Allplus | B8: 567.52 | C8: 12 | D8: 44669 | E8: 623.98 | F8: 13 | G8: 44669 | I8: =IF(A8=0,"",A8) -> Allplus | J8: =IF(B8=0,"",B8) -> 567.52 | K8: =IF(C8=0,"",C8) -> 12 | L8: =IF(D8=0,"",D8) -> 44669 | M8: =IF(E8=0,"",E8) -> 623.98 | N8: =IF(F8=0,"",F8) -> 13 | O8: =IF(G8=0,"",G8) -> 44669
A9: Antec | B9: 900.74 | C9: 17 | D9: 45341 | E9: 1000.9 | F9: 19 | G9: 45341 | I9: =IF(A9=0,"",A9) -> Antec | J9: =IF(B9=0,"",B9) -> 900.74 | K9: =IF(C9=0,"",C9) -> 17 | L9: =IF(D9=0,"",D9) -> 45341 | M9: =IF(E9=0,"",E9) -> 1000.9 | N9: =IF(F9=0,"",F9) -> 19 | O9: =IF(G9=0,"",G9) -> 45341
A10: ASUS | B10: 4531.83 | C10: 37 | D10: 45166 | E10: 5314.16 | F10: 44 | G10: 45166 | I10: =IF(A10=0,"",A10) -> ASUS | J10: =IF(B10=0,"",B10) -> 4531.83 | K10: =IF(C10=0,"",C10) -> 37 | L10: =IF(D10=0,"",D10) -> 45166 | M10: =IF(E10=0,"",E10) -> 5314.16 | N10: =IF(F10=0,"",F10) -> 44 | O10: =IF(G10=0,"",G10) -> 45166
A11: Intcomex | B11: 1487.03 | C11: 25 | D11: 44490 | E11: 1531.58 | F11: 26 | G11: 44490 | I11: =IF(A11=0,"",A11) -> Intcomex | J11: =IF(B11=0,"",B11) -> 1487.03 | K11: =IF(C11=0,"",C11) -> 25 | L11: =IF(D11=0,"",D11) -> 44490 | M11: =IF(E11=0,"",E11) -> 1531.58 | N11: =IF(F11=0,"",F11) -> 26 | O11: =IF(G11=0,"",G11) -> 44490
A12: Invid Computers | B12: 713.18 | C12: 8 | D12: 44949 | E12: 786.75 | F12: 9 | G12: 44949 | I12: =IF(A12=0,"",A12) -> Invid Computers | J12: =IF(B12=0,"",B12) -> 713.18 | K12: =IF(C12=0,"",C12) -> 8 | L12: =IF(D12=0,"",D12) -> 44949 | M12: =IF(E12=0,"",E12) -> 786.75 | N12: =IF(F12=0,"",F12) -> 9 | O12: =IF(G12=0,"",G12) -> 44949
A13: Mi PC Informatica - Invid Computers (Roger Wilco) | B13: 313 | C13: 3 | D13: 45729 | E13: 313 | F13: 3 | G13: 45729 | I13: =IF(A13=0,"",A13) -> Mi PC Informatica - Invid Computers (Roger Wilco) | J13: =IF(B13=0,"",B13) -> 313 | K13: =IF(C13=0,"",C13) -> 3 | L13: =IF(D13=0,"",D13) -> 45729 | M13: =IF(E13=0,"",E13) -> 313 | N13: =IF(F13=0,"",F13) -> 3 | O13: =IF(G13=0,"",G13) -> 45729
A14: PC Modd | B14: 214.93 | C14: 6 | D14: 45631 | E14: 214.93 | F14: 6 | G14: 45631 | I14: =IF(A14=0,"",A14) -> PC Modd | J14: =IF(B14=0,"",B14) -> 214.93 | K14: =IF(C14=0,"",C14) -> 6 | L14: =IF(D14=0,"",D14) -> 45631 | M14: =IF(E14=0,"",E14) -> 214.93 | N14: =IF(F14=0,"",F14) -> 6 | O14: =IF(G14=0,"",G14) -> 45631
A15: Radio Victoria | B15: 1171.89 | C15: 2 | D15: 45775 | E15: 1171.89 | F15: 2 | G15: 45775 | I15: =IF(A15=0,"",A15) -> Radio Victoria | J15: =IF(B15=0,"",B15) -> 1171.89 | K15: =IF(C15=0,"",C15) -> 2 | L15: =IF(D15=0,"",D15) -> 45775 | M15: =IF(E15=0,"",E15) -> 1171.89 | N15: =IF(F15=0,"",F15) -> 2 | O15: =IF(G15=0,"",G15) -> 45775
A16: Viewsonic - Febicom | B16: 1678.77 | C16: 7 | D16: 45656 | E16: 1678.77 | F16: 7 | G16: 45656 | I16: =IF(A16=0,"",A16) -> Viewsonic - Febicom | J16: =IF(B16=0,"",B16) -> 1678.77 | K16: =IF(C16=0,"",C16) -> 7 | L16: =IF(D16=0,"",D16) -> 45656 | M16: =IF(E16=0,"",E16) -> 1678.77 | N16: =IF(F16=0,"",F16) -> 7 | O16: =IF(G16=0,"",G16) -> 45656
A17: XFX | B17: 1757.99 | C17: 5 | D17: 45747 | E17: 2019.21 | F17: 6 | G17: 44667 | I17: =IF(A17=0,"",A17) -> XFX | J17: =IF(B17=0,"",B17) -> 1757.99 | K17: =IF(C17=0,"",C17) -> 5 | L17: =IF(D17=0,"",D17) -> 45747 | M17: =IF(E17=0,"",E17) -> 2019.21 | N17: =IF(F17=0,"",F17) -> 6 | O17: =IF(G17=0,"",G17) -> 44667
I18: =IF(A18=0,"",A18) | J18: =IF(B18=0,"",B18) | K18: =IF(C18=0,"",C18) | L18: =IF(D18=0,"",D18) | M18: =IF(E18=0,"",E18) | N18: =IF(F18=0,"",F18) | O18: =IF(G18=0,"",G18)
I19: =IF(A19=0,"",A19) | J19: =IF(B19=0,"",B19) | K19: =IF(C19=0,"",C19) | L19: =IF(D19=0,"",D19) | M19: =IF(E19=0,"",E19) | N19: =IF(F19=0,"",F19) | O19: =IF(G19=0,"",G19)
I20: =IF(A20=0,"",A20) | J20: =IF(B20=0,"",B20) | K20: =IF(C20=0,"",C20) | L20: =IF(D20=0,"",D20) | M20: =IF(E20=0,"",E20) | N20: =IF(F20=0,"",F20) | O20: =IF(G20=0,"",G20)
I21: =IF(A21=0,"",A21) | J21: =IF(B21=0,"",B21) | K21: =IF(C21=0,"",C21) | L21: =IF(D21=0,"",D21) | M21: =IF(E21=0,"",E21) | N21: =IF(F21=0,"",F21) | O21: =IF(G21=0,"",G21)
I22: =IF(A22=0,"",A22) | J22: =IF(B22=0,"",B22) | K22: =IF(C22=0,"",C22) | L22: =IF(D22=0,"",D22) | M22: =IF(E22=0,"",E22) | N22: =IF(F22=0,"",F22) | O22: =IF(G22=0,"",G22)
I23: =IF(A23=0,"",A23) | J23: =IF(B23=0,"",B23) | K23: =IF(C23=0,"",C23) | L23: =IF(D23=0,"",D23) | M23: =IF(E23=0,"",E23) | N23: =IF(F23=0,"",F23) | O23: =IF(G23=0,"",G23)
I24: =IF(A24=0,"",A24) | J24: =IF(B24=0,"",B24) | K24: =IF(C24=0,"",C24) | L24: =IF(D24=0,"",D24) | M24: =IF(E24=0,"",E24) | N24: =IF(F24=0,"",F24) | O24: =IF(G24=0,"",G24)
I25: =IF(A25=0,"",A25) | J25: =IF(B25=0,"",B25) | K25: =IF(C25=0,"",C25) | L25: =IF(D25=0,"",D25) | M25: =IF(E25=0,"",E25) | N25: =IF(F25=0,"",F25) | O25: =IF(G25=0,"",G25)
I26: =IF(A26=0,"",A26) | J26: =IF(B26=0,"",B26) | K26: =IF(C26=0,"",C26) | L26: =IF(D26=0,"",D26) | M26: =IF(E26=0,"",E26) | N26: =IF(F26=0,"",F26) | O26: =IF(G26=0,"",G26)

Sheet Gestores JAVIERS
A1: AGENTE | B1: JAVIERS
B3: SEMANA | C3: Valores
B4: 26W1 | E4: 26W2 | I4: GESTOR | J4: =B4 -> 26W1 | K4: =B4 -> 26W1 | M4: =E4 -> 26W2 | N4: =E4 -> 26W2
A5: GESTOR | B5: Monto Pendiente | C5: Unidades Pendientes | D5: Fecha de Compra | E5: Monto Pendiente | F5: Unidades Pendientes | G5: Fecha de Compra | J5: MONTO PENDIENTE | K5: UNIDADES PENDIENTES | L5: FECHA DE COMPRA | M5: MONTO PENDIENTE | N5: UNIDADES PENDIENTES | O5: FECHA DE COMPRA
A6: AS Tienda Tecno | B6: 60.16 | C6: 1 | D6: 44916 | E6: 60.16 | F6: 1 | G6: 44916 | I6: =IF(A6=0,"",A6) -> AS Tienda Tecno | J6: =IF(B6=0,"",B6) -> 60.16 | K6: =IF(C6=0,"",C6) -> 1 | L6: =IF(D6=0,"",D6) -> 44916 | M6: =IF(E6=0,"",E6) -> 60.16 | N6: =IF(F6=0,"",F6) -> 1 | O6: =IF(G6=0,"",G6) -> 44916
A7: ATW Media Corp | B7: 2527.15 | C7: 33 | D7: 45714 | E7: 2566.43 | F7: 34 | G7: 45714 | I7: =IF(A7=0,"",A7) -> ATW Media Corp | J7: =IF(B7=0,"",B7) -> 2527.15 | K7: =IF(C7=0,"",C7) -> 33 | L7: =IF(D7=0,"",D7) -> 45714 | M7: =IF(E7=0,"",E7) -> 2566.43 | N7: =IF(F7=0,"",F7) -> 34 | O7: =IF(G7=0,"",G7) -> 45714
A8: Elux Trading LLC | B8: 599.38 | C8: 6 | D8: 45652 | E8: 599.38 | F8: 6 | G8: 45652 | I8: =IF(A8=0,"",A8) -> Elux Trading LLC | J8: =IF(B8=0,"",B8) -> 599.38 | K8: =IF(C8=0,"",C8) -> 6 | L8: =IF(D8=0,"",D8) -> 45652 | M8: =IF(E8=0,"",E8) -> 599.38 | N8: =IF(F8=0,"",F8) -> 6 | O8: =IF(G8=0,"",G8) -> 45652
A9: GEIL | B9: 1000.68 | C9: 28 | D9: 44027 | I9: =IF(A9=0,"",A9) -> GEIL | J9: =IF(B9=0,"",B9) -> 1000.68 | K9: =IF(C9=0,"",C9) -> 28 | L9: =IF(D9=0,"",D9) -> 44027 | M9: =IF(E9=0,"",E9) | N9: =IF(F9=0,"",F9) | O9: =IF(G9=0,"",G9)
A10: Intermaco | B10: 181.1 | C10: 3 | D10: 44973 | E10: 181.1 | F10: 3 | G10: 44973 | I10: =IF(A10=0,"",A10) -> Intermaco | J10: =IF(B10=0,"",B10) -> 181.1 | K10: =IF(C10=0,"",C10) -> 3 | L10: =IF(D10=0,"",D10) -> 44973 | M10: =IF(E10=0,"",E10) -> 181.1 | N10: =IF(F10=0,"",F10) -> 3 | O10: =IF(G10=0,"",G10) -> 44973
A11: KTC | B11: 193.98 | C11: 2 | D11: 45889 | E11: 70.44 | F11: 1 | G11: 44671 | I11: =IF(A11=0,"",A11) -> KTC | J11: =IF(B11=0,"",B11) -> 193.98 | K11: =IF(C11=0,"",C11) -> 2 | L11: =IF(D11=0,"",D11) -> 45889 | M11: =IF(E11=0,"",E11) -> 70.44 | N11: =IF(F11=0,"",F11) -> 1 | O11: =IF(G11=0,"",G11) -> 44671
A12: Lenovo - Cronon Tecnología | B12: 2399.4 | C12: 4 | D12: 45560 | I12: =IF(A12=0,"",A12) -> Lenovo - Cronon Tecnología | J12: =IF(B12=0,"",B12) -> 2399.4 | K12: =IF(C12=0,"",C12) -> 4 | L12: =IF(D12=0,"",D12) -> 45560 | M12: =IF(E12=0,"",E12) | N12: =IF(F12=0,"",F12) | O12: =IF(G12=0,"",G12)
A13: MSI - Notebooks Almagro | B13: 1277.51 | C13: 7 | D13: 45660 | E13: 1543.05 | F13: 9 | G13: 44666 | I13: =IF(A13=0,"",A13) -> MSI - Notebooks Almagro | J13: =IF(B13=0,"",B13) -> 1277.51 | K13: =IF(C13=0,"",C13) -> 7 | L13: =IF(D13=0,"",D13) -> 45660 | M13: =IF(E13=0,"",E13) -> 1543.05 | N13: =IF(F13=0,"",F13) -> 9 | O13: =IF(G13=0,"",G13) -> 44666
A14: Siroco | B14: 393.2 | C14: 2 | D14: 45700 | E14: 393.2 | F14: 2 | G14: 45700 | I14: =IF(A14=0,"",A14) -> Siroco | J14: =IF(B14=0,"",B14) -> 393.2 | K14: =IF(C14=0,"",C14) -> 2 | L14: =IF(D14=0,"",D14) -> 45700 | M14: =IF(E14=0,"",E14) -> 393.2 | N14: =IF(F14=0,"",F14) -> 2 | O14: =IF(G14=0,"",G14) -> 45700
A15: Solution Box | B15: 17 | C15: 1 | D15: 45730 | E15: 17 | F15: 1 | G15: 45730 | I15: =IF(A15=0,"",A15) -> Solution Box | J15: =IF(B15=0,"",B15) -> 17 | K15: =IF(C15=0,"",C15) -> 1 | L15: =IF(D15=0,"",D15) -> 45730 | M15: =IF(E15=0,"",E15) -> 17 | N15: =IF(F15=0,"",F15) -> 1 | O15: =IF(G15=0,"",G15) -> 45730
A16: Synnex - Techdata (AVT TECHNOLOGY) | B16: 5453.53 | C16: 23 | D16: 45693 | E16: 5453.53 | F16: 23 | G16: 45693 | I16: =IF(A16=0,"",A16) -> Synnex - Techdata (AVT TECHNOLOGY) | J16: =IF(B16=0,"",B16) -> 5453.53 | K16: =IF(C16=0,"",C16) -> 23 | L16: =IF(D16=0,"",D16) -> 45693 | M16: =IF(E16=0,"",E16) -> 5453.53 | N16: =IF(F16=0,"",F16) -> 23 | O16: =IF(G16=0,"",G16) -> 45693
A17: Techcom | B17: 3509.23 | C17: 4 | D17: 45400 | E17: 3509.23 | F17: 4 | G17: 45400 | I17: =IF(A17=0,"",A17) -> Techcom | J17: =IF(B17=0,"",B17) -> 3509.23 | K17: =IF(C17=0,"",C17) -> 4 | L17: =IF(D17=0,"",D17) -> 45400 | M17: =IF(E17=0,"",E17) -> 3509.23 | N17: =IF(F17=0,"",F17) -> 4 | O17: =IF(G17=0,"",G17) -> 45400
I18: =IF(A18=0,"",A18) | J18: =IF(B18=0,"",B18) | K18: =IF(C18=0,"",C18) | L18: =IF(D18=0,"",D18) | M18: =IF(E18=0,"",E18) | N18: =IF(F18=0,"",F18) | O18: =IF(G18=0,"",G18)
I19: =IF(A19=0,"",A19) | J19: =IF(B19=0,"",B19) | K19: =IF(C19=0,"",C19) | L19: =IF(D19=0,"",D19) | M19: =IF(E19=0,"",E19) | N19: =IF(F19=0,"",F19) | O19: =IF(G19=0,"",G19)
I20: =IF(A20=0,"",A20) | J20: =IF(B20=0,"",B20) | K20: =IF(C20=0,"",C20) | L20: =IF(D20=0,"",D20) | M20: =IF(E20=0,"",E20) | N20: =IF(F20=0,"",F20) | O20: =IF(G20=0,"",G20)
I21: =IF(A21=0,"",A21) | J21: =IF(B21=0,"",B21) | K21: =IF(C21=0,"",C21) | L21: =IF(D21=0,"",D21) | M21: =IF(E21=0,"",E21) | N21: =IF(F21=0,"",F21) | O21: =IF(G21=0,"",G21)
I22: =IF(A22=0,"",A22) | J22: =IF(B22=0,"",B22) | K22: =IF(C22=0,"",C22) | L22: =IF(D22=0,"",D22) | M22: =IF(E22=0,"",E22) | N22: =IF(F22=0,"",F22) | O22: =IF(G22=0,"",G22)
I23: =IF(A23=0,"",A23) | J23: =IF(B23=0,"",B23) | K23: =IF(C23=0,"",C23) | L23: =IF(D23=0,"",D23) | M23: =IF(E23=0,"",E23) | N23: =IF(F23=0,"",F23) | O23: =IF(G23=0,"",G23)
I24: =IF(A24=0,"",A24) | J24: =IF(B24=0,"",B24) | K24: =IF(C24=0,"",C24) | L24: =IF(D24=0,"",D24) | M24: =IF(E24=0,"",E24) | N24: =IF(F24=0,"",F24) | O24: =IF(G24=0,"",G24)
I25: =IF(A25=0,"",A25) | J25: =IF(B25=0,"",B25) | K25: =IF(C25=0,"",C25) | L25: =IF(D25=0,"",D25) | M25: =IF(E25=0,"",E25) | N25: =IF(F25=0,"",F25) | O25: =IF(G25=0,"",G25)
I26: =IF(A26=0,"",A26) | J26: =IF(B26=0,"",B26) | K26: =IF(C26=0,"",C26) | L26: =IF(D26=0,"",D26) | M26: =IF(E26=0,"",E26) | N26: =IF(F26=0,"",F26) | O26: =IF(G26=0,"",G26)

Sheet Gestores MATIASNG
A1: AGENTE | B1: MATIASNG
B3: SEMANA | C3: Valores
B4: 26W1 | E4: 26W2 | I4: GESTOR | J4: =B4 -> 26W1 | K4: =B4 -> 26W1 | M4: =E4 -> 26W2 | N4: =E4 -> 26W2
A5: GESTOR | B5: Monto Pendiente | C5: Unidades Pendientes | D5: Fecha de Compra | E5: Monto Pendiente | F5: Unidades Pendientes | G5: Fecha de Compra | J5: MONTO PENDIENTE | K5: UNIDADES PENDIENTES | L5: FECHA DE COMPRA | M5: MONTO PENDIENTE | N5: UNIDADES PENDIENTES | O5: FECHA DE COMPRA
A6: Adata - Modulos | B6: 2403.99 | C6: 45 | D6: 44079 | E6: 2776.87 | F6: 50 | G6: 44079 | I6: =IF(A6=0,"",A6) -> Adata - Modulos | J6: =IF(B6=0,"",B6) -> 2403.99 | K6: =IF(C6=0,"",C6) -> 45 | L6: =IF(D6=0,"",D6) -> 44079 | M6: =IF(E6=0,"",E6) -> 2776.87 | N6: =IF(F6=0,"",F6) -> 50 | O6: =IF(G6=0,"",G6) -> 44079
A7: Adata - Perifericos | B7: 1369.88 | C7: 18 | D7: 44642 | E7: 1369.88 | F7: 18 | G7: 44642 | I7: =IF(A7=0,"",A7) -> Adata - Perifericos | J7: =IF(B7=0,"",B7) -> 1369.88 | K7: =IF(C7=0,"",C7) -> 18 | L7: =IF(D7=0,"",D7) -> 44642 | M7: =IF(E7=0,"",E7) -> 1369.88 | N7: =IF(F7=0,"",F7) -> 18 | O7: =IF(G7=0,"",G7) -> 44642
A8: Distecna | B8: 942.54 | C8: 7 | D8: 45608 | E8: 942.54 | F8: 7 | G8: 45608 | I8: =IF(A8=0,"",A8) -> Distecna | J8: =IF(B8=0,"",B8) -> 942.54 | K8: =IF(C8=0,"",C8) -> 7 | L8: =IF(D8=0,"",D8) -> 45608 | M8: =IF(E8=0,"",E8) -> 942.54 | N8: =IF(F8=0,"",F8) -> 7 | O8: =IF(G8=0,"",G8) -> 45608
A9: Ingram Micro | B9: 1791.05 | C9: 9 | D9: 45714 | E9: 1791.05 | F9: 9 | G9: 45714 | I9: =IF(A9=0,"",A9) -> Ingram Micro | J9: =IF(B9=0,"",B9) -> 1791.05 | K9: =IF(C9=0,"",C9) -> 9 | L9: =IF(D9=0,"",D9) -> 45714 | M9: =IF(E9=0,"",E9) -> 1791.05 | N9: =IF(F9=0,"",F9) -> 9 | O9: =IF(G9=0,"",G9) -> 45714
A10: Inno3D | B10: 3443.41 | C10: 7 | D10: 45768 | E10: 3443.41 | F10: 7 | G10: 45768 | I10: =IF(A10=0,"",A10) -> Inno3D | J10: =IF(B10=0,"",B10) -> 3443.41 | K10: =IF(C10=0,"",C10) -> 7 | L10: =IF(D10=0,"",D10) -> 45768 | M10: =IF(E10=0,"",E10) -> 3443.41 | N10: =IF(F10=0,"",F10) -> 7 | O10: =IF(G10=0,"",G10) -> 45768
A11: Micro Informatica | B11: 1400.16 | C11: 26 | D11: 45490 | E11: 1766.87 | F11: 36 | G11: 45341 | I11: =IF(A11=0,"",A11) -> Micro Informatica | J11: =IF(B11=0,"",B11) -> 1400.16 | K11: =IF(C11=0,"",C11) -> 26 | L11: =IF(D11=0,"",D11) -> 45490 | M11: =IF(E11=0,"",E11) -> 1766.87 | N11: =IF(F11=0,"",F11) -> 36 | O11: =IF(G11=0,"",G11) -> 45341
A12: Micro Informatica - AMD | B12: 6771.53 | C12: 28 | D12: 44484 | E12: 9193.9 | F12: 37 | G12: 44484 | I12: =IF(A12=0,"",A12) -> Micro Informatica - AMD | J12: =IF(B12=0,"",B12) -> 6771.53 | K12: =IF(C12=0,"",C12) -> 28 | L12: =IF(D12=0,"",D12) -> 44484 | M12: =IF(E12=0,"",E12) -> 9193.9 | N12: =IF(F12=0,"",F12) -> 37 | O12: =IF(G12=0,"",G12) -> 44484
A13: Micro Informatica - ASUS | B13: 6618.72 | C13: 23 | D13: 45562 | E13: 7203.14 | F13: 25 | G13: 45562 | I13: =IF(A13=0,"",A13) -> Micro Informatica - ASUS | J13: =IF(B13=0,"",B13) -> 6618.72 | K13: =IF(C13=0,"",C13) -> 23 | L13: =IF(D13=0,"",D13) -> 45562 | M13: =IF(E13=0,"",E13) -> 7203.14 | N13: =IF(F13=0,"",F13) -> 25 | O13: =IF(G13=0,"",G13) -> 45562
A14: Micro Informatica - Corsair | B14: 1532.12 | C14: 24 | D14: 45462 | E14: 1577.41 | F14: 25 | G14: 45462 | I14: =IF(A14=0,"",A14) -> Micro Informatica - Corsair | J14: =IF(B14=0,"",B14) -> 1532.12 | K14: =IF(C14=0,"",C14) -> 24 | L14: =IF(D14=0,"",D14) -> 45462 | M14: =IF(E14=0,"",E14) -> 1577.41 | N14: =IF(F14=0,"",F14) -> 25 | O14: =IF(G14=0,"",G14) -> 45462
A15: Samsung - Inspección | B15: 1722.74 | C15: 6 | D15: 45748 | E15: 793.5 | F15: 1 | G15: 45917 | I15: =IF(A15=0,"",A15) -> Samsung - Inspección | J15: =IF(B15=0,"",B15) -> 1722.74 | K15: =IF(C15=0,"",C15) -> 6 | L15: =IF(D15=0,"",D15) -> 45748 | M15: =IF(E15=0,"",E15) -> 793.5 | N15: =IF(F15=0,"",F15) -> 1 | O15: =IF(G15=0,"",G15) -> 45917
A16: Zotac | B16: 1973.97 | C16: 5 | D16: 45481 | E16: 1973.97 | F16: 5 | G16: 45481 | I16: =IF(A16=0,"",A16) -> Zotac | J16: =IF(B16=0,"",B16) -> 1973.97 | K16: =IF(C16=0,"",C16) -> 5 | L16: =IF(D16=0,"",D16) -> 45481 | M16: =IF(E16=0,"",E16) -> 1973.97 | N16: =IF(F16=0,"",F16) -> 5 | O16: =IF(G16=0,"",G16) -> 45481
A17: Zotac - M2 | B17: 4510.45 | C17: 4 | D17: 44658 | E17: 4510.45 | F17: 4 | G17: 44658 | I17: =IF(A17=0,"",A17) -> Zotac - M2 | J17: =IF(B17=0,"",B17) -> 4510.45 | K17: =IF(C17=0,"",C17) -> 4 | L17: =IF(D17=0,"",D17) -> 44658 | M17: =IF(E17=0,"",E17) -> 4510.45 | N17: =IF(F17=0,"",F17) -> 4 | O17: =IF(G17=0,"",G17) -> 44658
I18: =IF(A18=0,"",A18) | J18: =IF(B18=0,"",B18) | K18: =IF(C18=0,"",C18) | L18: =IF(D18=0,"",D18) | M18: =IF(E18=0,"",E18) | N18: =IF(F18=0,"",F18) | O18: =IF(G18=0,"",G18)
I19: =IF(A19=0,"",A19) | J19: =IF(B19=0,"",B19) | K19: =IF(C19=0,"",C19) | L19: =IF(D19=0,"",D19) | M19: =IF(E19=0,"",E19) | N19: =IF(F19=0,"",F19) | O19: =IF(G19=0,"",G19)
I20: =IF(A20=0,"",A20) | J20: =IF(B20=0,"",B20) | K20: =IF(C20=0,"",C20) | L20: =IF(D20=0,"",D20) | M20: =IF(E20=0,"",E20) | N20: =IF(F20=0,"",F20) | O20: =IF(G20=0,"",G20)
I21: =IF(A21=0,"",A21) | J21: =IF(B21=0,"",B21) | K21: =IF(C21=0,"",C21) | L21: =IF(D21=0,"",D21) | M21: =IF(E21=0,"",E21) | N21: =IF(F21=0,"",F21) | O21: =IF(G21=0,"",G21)
I22: =IF(A22=0,"",A22) | J22: =IF(B22=0,"",B22) | K22: =IF(C22=0,"",C22) | L22: =IF(D22=0,"",D22) | M22: =IF(E22=0,"",E22) | N22: =IF(F22=0,"",F22) | O22: =IF(G22=0,"",G22)
I23: =IF(A23=0,"",A23) | J23: =IF(B23=0,"",B23) | K23: =IF(C23=0,"",C23) | L23: =IF(D23=0,"",D23) | M23: =IF(E23=0,"",E23) | N23: =IF(F23=0,"",F23) | O23: =IF(G23=0,"",G23)
I24: =IF(A24=0,"",A24) | J24: =IF(B24=0,"",B24) | K24: =IF(C24=0,"",C24) | L24: =IF(D24=0,"",D24) | M24: =IF(E24=0,"",E24) | N24: =IF(F24=0,"",F24) | O24: =IF(G24=0,"",G24)
I25: =IF(A25=0,"",A25) | J25: =IF(B25=0,"",B25) | K25: =IF(C25=0,"",C25) | L25: =IF(D25=0,"",D25) | M25: =IF(E25=0,"",E25) | N25: =IF(F25=0,"",F25) | O25: =IF(G25=0,"",G25)
I26: =IF(A26=0,"",A26) | J26: =IF(B26=0,"",B26) | K26: =IF(C26=0,"",C26) | L26: =IF(D26=0,"",D26) | M26: =IF(E26=0,"",E26) | N26: =IF(F26=0,"",F26) | O26: =IF(G26=0,"",G26)

Sheet Gestores REINHART
A1: AGENTE | B1: REINHART
B3: SEMANA | C3: Valores
B4: 26W1 | E4: 26W2 | I4: GESTOR | J4: =B4 -> 26W1 | K4: =B4 -> 26W1 | M4: =E4 -> 26W2 | N4: =E4 -> 26W2
A5: GESTOR | B5: Monto Pendiente | C5: Unidades Pendientes | D5: Fecha de Compra | E5: Monto Pendiente | F5: Unidades Pendientes | G5: Fecha de Compra | J5: MONTO PENDIENTE | K5: UNIDADES PENDIENTES | L5: FECHA DE COMPRA | M5: MONTO PENDIENTE | N5: UNIDADES PENDIENTES | O5: FECHA DE COMPRA
A6: ASRock - Dreamshop | B6: 4204.95 | C6: 34 | D6: 44238 | E6: 4706.92 | F6: 41 | G6: 44238 | I6: =IF(A6=0,"",A6) -> ASRock - Dreamshop | J6: =IF(B6=0,"",B6) -> 4204.95 | K6: =IF(C6=0,"",C6) -> 34 | L6: =IF(D6=0,"",D6) -> 44238 | M6: =IF(E6=0,"",E6) -> 4706.92 | N6: =IF(F6=0,"",F6) -> 41 | O6: =IF(G6=0,"",G6) -> 44238
A7: ASRock - Monitores | B7: 1961.77 | C7: 17 | D7: 45656 | E7: 2212.68 | F7: 20 | G7: 45656 | I7: =IF(A7=0,"",A7) -> ASRock - Monitores | J7: =IF(B7=0,"",B7) -> 1961.77 | K7: =IF(C7=0,"",C7) -> 17 | L7: =IF(D7=0,"",D7) -> 45656 | M7: =IF(E7=0,"",E7) -> 2212.68 | N7: =IF(F7=0,"",F7) -> 20 | O7: =IF(G7=0,"",G7) -> 45656
A8: Cougar | B8: 2106.86 | C8: 39 | D8: 45341 | E8: 1566.23 | F8: 30 | G8: 45341 | I8: =IF(A8=0,"",A8) -> Cougar | J8: =IF(B8=0,"",B8) -> 2106.86 | K8: =IF(C8=0,"",C8) -> 39 | L8: =IF(D8=0,"",D8) -> 45341 | M8: =IF(E8=0,"",E8) -> 1566.23 | N8: =IF(F8=0,"",F8) -> 30 | O8: =IF(G8=0,"",G8) -> 45341
A9: GN Hearing Care Corporation | B9: 143.73 | C9: 1 | D9: 45880 | E9: 353.52 | F9: 3 | G9: 44668 | I9: =IF(A9=0,"",A9) -> GN Hearing Care Corporation | J9: =IF(B9=0,"",B9) -> 143.73 | K9: =IF(C9=0,"",C9) -> 1 | L9: =IF(D9=0,"",D9) -> 45880 | M9: =IF(E9=0,"",E9) -> 353.52 | N9: =IF(F9=0,"",F9) -> 3 | O9: =IF(G9=0,"",G9) -> 44668
A10: Intel | B10: 555.87 | C10: 1 | D10: 45930 | E10: 844.23 | F10: 2 | G10: 44669 | I10: =IF(A10=0,"",A10) -> Intel | J10: =IF(B10=0,"",B10) -> 555.87 | K10: =IF(C10=0,"",C10) -> 1 | L10: =IF(D10=0,"",D10) -> 45930 | M10: =IF(E10=0,"",E10) -> 844.23 | N10: =IF(F10=0,"",F10) -> 2 | O10: =IF(G10=0,"",G10) -> 44669
A11: LG - Gusmat | B11: 90.52 | C11: 1 | D11: 45772 | E11: 295.33 | F11: 2 | G11: 45737 | I11: =IF(A11=0,"",A11) -> LG - Gusmat | J11: =IF(B11=0,"",B11) -> 90.52 | K11: =IF(C11=0,"",C11) -> 1 | L11: =IF(D11=0,"",D11) -> 45772 | M11: =IF(E11=0,"",E11) -> 295.33 | N11: =IF(F11=0,"",F11) -> 2 | O11: =IF(G11=0,"",G11) -> 45737
A12: M2 Gaming | B12: 1467.57 | C12: 2 | D12: 45509 | E12: 1467.57 | F12: 2 | G12: 44662 | I12: =IF(A12=0,"",A12) -> M2 Gaming | J12: =IF(B12=0,"",B12) -> 1467.57 | K12: =IF(C12=0,"",C12) -> 2 | L12: =IF(D12=0,"",D12) -> 45509 | M12: =IF(E12=0,"",E12) -> 1467.57 | N12: =IF(F12=0,"",F12) -> 2 | O12: =IF(G12=0,"",G12) -> 44662
A13: Ma Labs | B13: 470.73 | C13: 3 | D13: 45477 | E13: 470.73 | F13: 3 | G13: 45477 | I13: =IF(A13=0,"",A13) -> Ma Labs | J13: =IF(B13=0,"",B13) -> 470.73 | K13: =IF(C13=0,"",C13) -> 3 | L13: =IF(D13=0,"",D13) -> 45477 | M13: =IF(E13=0,"",E13) -> 470.73 | N13: =IF(F13=0,"",F13) -> 3 | O13: =IF(G13=0,"",G13) -> 45477
A14: Patriot | B14: 2302.57 | C14: 34 | D14: 44692 | E14: 14.43 | F14: 1 | G14: 44672 | I14: =IF(A14=0,"",A14) -> Patriot | J14: =IF(B14=0,"",B14) -> 2302.57 | K14: =IF(C14=0,"",C14) -> 34 | L14: =IF(D14=0,"",D14) -> 44692 | M14: =IF(E14=0,"",E14) -> 14.43 | N14: =IF(F14=0,"",F14) -> 1 | O14: =IF(G14=0,"",G14) -> 44672
A15: PC Arts | B15: 92.71 | C15: 2 | D15: 45730 | E15: 92.71 | F15: 2 | G15: 45730 | I15: =IF(A15=0,"",A15) -> PC Arts | J15: =IF(B15=0,"",B15) -> 92.71 | K15: =IF(C15=0,"",C15) -> 2 | L15: =IF(D15=0,"",D15) -> 45730 | M15: =IF(E15=0,"",E15) -> 92.71 | N15: =IF(F15=0,"",F15) -> 2 | O15: =IF(G15=0,"",G15) -> 45730
A16: PLPC | B16: 625.17 | C16: 8 | D16: 44728 | E16: 625.17 | F16: 8 | G16: 44728 | I16: =IF(A16=0,"",A16) -> PLPC | J16: =IF(B16=0,"",B16) -> 625.17 | K16: =IF(C16=0,"",C16) -> 8 | L16: =IF(D16=0,"",D16) -> 44728 | M16: =IF(E16=0,"",E16) -> 625.17 | N16: =IF(F16=0,"",F16) -> 8 | O16: =IF(G16=0,"",G16) -> 44728
A17: PLPC - AMD | B17: 967.09 | C17: 3 | D17: 45930 | E17: 1223.71 | F17: 4 | G17: 44660 | I17: =IF(A17=0,"",A17) -> PLPC - AMD | J17: =IF(B17=0,"",B17) -> 967.09 | K17: =IF(C17=0,"",C17) -> 3 | L17: =IF(D17=0,"",D17) -> 45930 | M17: =IF(E17=0,"",E17) -> 1223.71 | N17: =IF(F17=0,"",F17) -> 4 | O17: =IF(G17=0,"",G17) -> 44660
... A21: UsTech - Kingston | B21: 130.36 | C21: 3 | D21: 45517 | E21: 141.55 | F21: 4 | G21: 45517 | I21: =IF(A21=0,"",A21) -> UsTech - Kingston | J21: =IF(B21=0,"",B21) -> 130.36 | K21: =IF(C21=0,"",C21) -> 3 | L21: =IF(D21=0,"",D21) -> 45517 | M21: =IF(E21=0,"",E21) -> 141.55 | N21: =IF(F21=0,"",F21) -> 4 | O21: =IF(G21=0,"",G21) -> 45517
I22: =IF(A22=0,"",A22) | J22: =IF(B22=0,"",B22) | K22: =IF(C22=0,"",C22) | L22: =IF(D22=0,"",D22) | M22: =IF(E22=0,"",E22) | N22: =IF(F22=0,"",F22) | O22: =IF(G22=0,"",G22)
I23: =IF(A23=0,"",A23) | J23: =IF(B23=0,"",B23) | K23: =IF(C23=0,"",C23) | L23: =IF(D23=0,"",D23) | M23: =IF(E23=0,"",E23) | N23: =IF(F23=0,"",F23) | O23: =IF(G23=0,"",G23)
I24: =IF(A24=0,"",A24) | J24: =IF(B24=0,"",B24) | K24: =IF(C24=0,"",C24) | L24: =IF(D24=0,"",D24) | M24: =IF(E24=0,"",E24) | N24: =IF(F24=0,"",F24) | O24: =IF(G24=0,"",G24)
I25: =IF(A25=0,"",A25) | J25: =IF(B25=0,"",B25) | K25: =IF(C25=0,"",C25) | L25: =IF(D25=0,"",D25) | M25: =IF(E25=0,"",E25) | N25: =IF(F25=0,"",F25) | O25: =IF(G25=0,"",G25)
I26: =IF(A26=0,"",A26) | J26: =IF(B26=0,"",B26) | K26: =IF(C26=0,"",C26) | L26: =IF(D26=0,"",D26) | M26: =IF(E26=0,"",E26) | N26: =IF(F26=0,"",F26) | O26: =IF(G26=0,"",G26)

Sheet ListaGestores
A1: GESTOR | B1: AGENTE
A2: Acegame | B2: ALANC
A3: ACER - Techcom | B3: EMAA
A4: ADATA TECHCOM | B4: JAVIERS
A5: Adata - Modulos | B5: MATIASNG
A6: Adata - Perifericos | B6: MATIASNG
A7: AFOX | B7: MATIASNG
A8: AIR | B8: EMAA
A9: Allplus | B9: EMAA
A10: Allplus - Gigabyte | B10: EMAA
A11: Allplus - Toshiba | B11: EMAA
A12: AMD - Retail | B12: MATIASNG
... A29: Circulo Vision | B29: ALANC
A30: COMPRA GAMER (Hurlingham)
A31: Cooler Master | B31: JAVIERS
A32: Corcisa | B32: ALANC
A33: Cougar | B33: REINHART
A34: Cougar - Taiwan | B34: REINHART
A35: Dahua | B35: ALANC
A36: Deepcool Beijing | B36: ALANC
A37: Dell | B37: MATIASNG
A38: Dellorean | B38: ALANC
A39: Distecna | B39: MATIASNG
A40: Elit | B40: ALANC
A41: Elux Trading LLC | B41: JAVIERS
A42: Energy Holdings | B42: ALANC
... A45: FAG Sistems | B45: JAVIERS
A46: FEDEX
A47: Flayma | B47: ALANC
A48: Free | B48: ALANC
A49: GEIL | B49: JAVIERS
A50: Gigabyte | B50: REINHART
A51: Gigabyte - LEBA | B51: REINHART
A52: Glorious | B52: REINHART
A53: GN Hearing Care Corporation | B53: REINHART
A54: Grupo Fixon | B54: JAVIERS
A55: Grupo Núcleo | B55: ALANC
A56: GTC RIBBON (RioToro) | B56: JAVIERS
A57: HDC | B57: EMAA
A58: HK Torosus | B58: MATIASNG
...
